<?xml version="1.0" encoding="utf-8"?>
<!-- =================================================================================== -->
<!-- |    This document was autogenerated by xacro from /root/catkin_ws/src/dobot_description/urdf/scenario.xacro | -->
<!-- |    EDITING THIS FILE BY HAND IS NOT RECOMMENDED                                 | -->
<!-- =================================================================================== -->
<robot name="scenario">
  <!-- Created on: Mai, 2019 Author: Philip Frieling -->
  <!-- Defining usefull macros -->
  <!-- Created on: Mai, 2019 Author: Philip Frieling -->
  <gazebo>
    <plugin filename="libgazebo_ros_control.so" name="gazebo_ros_control_Dobot_Rail">
      <robotNamespace>Dobot_Rail</robotNamespace>
      <robotParam>robot_description</robotParam>
    </plugin>
    <plugin filename="libdobotSim.so" name="dobotSim_Dobot_Rail">
      <robotNamespace>Dobot_Rail</robotNamespace>
    </plugin>
  </gazebo>
  <link name="world"/>
  <joint name="Dobot_Rail_fixed" type="fixed">
    <parent link="world"/>
    <child link="Dobot_Rail_Rail"/>
    <origin rpy="0.0 0.0 0.0" xyz="0.0 0.0 0.05"/>
  </joint>
  <link name="Dobot_Rail_Rail">
    <inertial>
      <origin rpy="0 0 0" xyz="0 -0.5 -0.02"/>
      <mass value="4.7"/>
      <inertia ixx="0.392293333333" ixy="0" ixz="0" iyy="0.00125333333333" iyz="0" izz="0.392293333333"/>
    </inertial>
    <visual name="base_vis">
      <origin rpy="0 0 0" xyz="0 0 0"/>
      <geometry>
        <mesh filename="package://dobot_description/meshes/rail.dae" scale="1 1 1"/>
      </geometry>
    </visual>
    <collision name="tool_col">
      <origin rpy="0 0 0" xyz="0 -0.5 -0.02"/>
      <geometry>
        <box size="0.04 1.0 0.04"/>
      </geometry>
    </collision>
  </link>
  <joint name="Dobot_Rail_rail_joint" type="prismatic">
    <parent link="Dobot_Rail_Rail"/>
    <child link="Dobot_Rail"/>
    <origin rpy="0 0 0" xyz="0.0 0.0 0.05"/>
    <axis xyz="0 1 0"/>
    <dynamics damping="1.0" friction="10.0"/>
    <limit effort="5000.0" lower="-1.0" upper="0.001" velocity="1.0"/>
  </joint>
  <gazebo reference="Dobot_Rail_rail_joint">
    <implicitSpringDamper>True</implicitSpringDamper>
  </gazebo>
  <transmission name="Dobot_Rail_rail_transmission">
    <type>transmission_interface/SimpleTransmission</type>
    <joint name="Dobot_Rail_rail_joint">
      <hardwareInterface>hardware_interface/EffortJointInterface</hardwareInterface>
    </joint>
    <actuator name="Dobot_Rail_rail_motor">
      <hardwareInterface>hardware_interface/EffortJointInterface</hardwareInterface>
      <mechanicalReduction>1</mechanicalReduction>
    </actuator>
  </transmission>
  <link name="Dobot_Rail">
    <inertial>
      <origin rpy="0 0 0" xyz="0 0 0.0"/>
      <mass value="1.0"/>
      <inertia ixx="0.00346666666667" ixy="0" ixz="0" iyy="0.00346666666667" iyz="0" izz="0.00666666666667"/>
    </inertial>
    <visual name="stand_vis">
      <origin rpy="0 -0.0 0" xyz="0 0 0"/>
      <geometry>
        <mesh filename="package://dobot_description/meshes/stand.dae" scale="1 1 1"/>
      </geometry>
    </visual>
    <collision name="stand_col">
      <origin rpy="0 0 0" xyz="0 0 -0.02"/>
      <geometry>
        <box size="0.16 0.16 0.04"/>
      </geometry>
    </collision>
  </link>
  <link name="Dobot_Rail_base_link">
    <inertial>
      <origin rpy="0 0 0" xyz="0 0 0.055"/>
      <mass value="0.75"/>
      <inertia ixx="0.000703125" ixy="0" ixz="0" iyy="0.000703125" iyz="0" izz="0.000703125"/>
    </inertial>
    <visual name="base_vis">
      <origin rpy="0 -0.0 0" xyz="0 0 0"/>
      <geometry>
        <mesh filename="package://dobot_description/meshes/base.dae" scale="1 1 1"/>
      </geometry>
    </visual>
    <collision name="base_vis">
      <origin rpy="0 0 0" xyz="0 0 0.055"/>
      <geometry>
        <cylinder length="0.11" radius="0.045"/>
      </geometry>
    </collision>
  </link>
  <joint name="Dobot_Rail_base_joint" type="revolute">
    <parent link="Dobot_Rail"/>
    <child link="Dobot_Rail_base_link"/>
    <origin rpy="0.0 0.0 0.0" xyz="0.0 0.0 0.0"/>
    <axis xyz="0 0 1"/>
    <dynamics damping="1.0" friction="1.0"/>
    <limit effort="50.0" lower="-3.0" upper="3.0" velocity="3.1415"/>
  </joint>
  <gazebo reference="Dobot_Rail_base_joint">
    <implicitSpringDamper>True</implicitSpringDamper>
  </gazebo>
  <transmission name="Dobot_Rail_base_transmission">
    <type>transmission_interface/SimpleTransmission</type>
    <joint name="Dobot_Rail_base_joint">
      <hardwareInterface>hardware_interface/EffortJointInterface</hardwareInterface>
    </joint>
    <actuator name="Dobot_Rail_base_motor">
      <hardwareInterface>hardware_interface/EffortJointInterface</hardwareInterface>
      <mechanicalReduction>1</mechanicalReduction>
    </actuator>
  </transmission>
  <link name="Dobot_Rail_shoulder_link">
    <inertial>
      <origin rpy="0 0 0" xyz="-0.03 0 0.08"/>
      <mass value="0.3"/>
      <inertia ixx="0.0006025" ixy="0" ixz="0" iyy="0.0007225" iyz="0" izz="0.0002"/>
    </inertial>
    <visual name="shoulder_vis">
      <origin rpy="0 -0.0 0" xyz="0 0 0"/>
      <geometry>
        <mesh filename="package://dobot_description/meshes/shoulder.dae" scale="1 1 1"/>
      </geometry>
    </visual>
    <collision name="shoulder_col">
      <origin rpy="0 0 0" xyz="-0.03 0 0.08"/>
      <geometry>
        <box size="0.08 0.04 0.15"/>
      </geometry>
    </collision>
  </link>
  <joint name="Dobot_Rail_shoulder_joint" type="revolute">
    <parent link="Dobot_Rail_base_link"/>
    <child link="Dobot_Rail_shoulder_link"/>
    <origin rpy="0.0 0.0 0.0" xyz="0.0 0.0 0.082"/>
    <axis xyz="0 1 0"/>
    <dynamics damping="1.0" friction="1.0"/>
    <limit effort="5.0" lower="-3.0" upper="3.0" velocity="3.1415"/>
  </joint>
  <gazebo reference="Dobot_Rail_shoulder_joint">
    <implicitSpringDamper>True</implicitSpringDamper>
  </gazebo>
  <transmission name="Dobot_Rail_shoulder_transmission">
    <type>transmission_interface/SimpleTransmission</type>
    <joint name="Dobot_Rail_shoulder_joint">
      <hardwareInterface>hardware_interface/EffortJointInterface</hardwareInterface>
    </joint>
    <actuator name="Dobot_Rail_shoulder_motor">
      <hardwareInterface>hardware_interface/EffortJointInterface</hardwareInterface>
      <mechanicalReduction>1</mechanicalReduction>
    </actuator>
  </transmission>
  <link name="Dobot_Rail_elbow_link">
    <inertial>
      <origin rpy="0 0 0" xyz="0.07 0 0.02"/>
      <mass value="0.3"/>
      <inertia ixx="0.00013" ixy="0" ixz="0" iyy="0.0009925" iyz="0" izz="0.0009425"/>
    </inertial>
    <visual name="elbow_vis">
      <origin rpy="0 -0.0 0" xyz="0 0 0"/>
      <geometry>
        <mesh filename="package://dobot_description/meshes/elbow.dae" scale="1 1 1"/>
      </geometry>
    </visual>
    <collision name="elbow_col">
      <origin rpy="0 0 0" xyz="0.07 0 0.02"/>
      <geometry>
        <box size="0.19 0.04 0.06"/>
      </geometry>
    </collision>
  </link>
  <joint name="Dobot_Rail_elbow_joint" type="revolute">
    <parent link="Dobot_Rail_shoulder_link"/>
    <child link="Dobot_Rail_elbow_link"/>
    <origin rpy="0.0 0.0 0.0" xyz="0.0 0.0 0.135"/>
    <axis xyz="0 1 0"/>
    <dynamics damping="1.0" friction="1.0"/>
    <limit effort="50.0" lower="-3.0" upper="3.0" velocity="3.1415"/>
  </joint>
  <gazebo reference="Dobot_Rail_elbow_joint">
    <implicitSpringDamper>True</implicitSpringDamper>
  </gazebo>
  <transmission name="Dobot_Rail_elbow_transmission">
    <type>transmission_interface/SimpleTransmission</type>
    <joint name="Dobot_Rail_elbow_joint">
      <hardwareInterface>hardware_interface/EffortJointInterface</hardwareInterface>
    </joint>
    <actuator name="Dobot_Rail_elbow_motor">
      <hardwareInterface>hardware_interface/EffortJointInterface</hardwareInterface>
      <mechanicalReduction>1</mechanicalReduction>
    </actuator>
  </transmission>
  <link name="Dobot_Rail_hand_link">
    <inertial>
      <origin rpy="0 0 0" xyz="0.05 0 0.005"/>
      <mass value="0.2"/>
      <inertia ixx="4.83333333333e-05" ixy="0" ixz="0" iyy="0.000208333333333" iyz="0" izz="0.000173333333333"/>
    </inertial>
    <visual name="hand_vis">
      <origin rpy="0 0 0" xyz="0 0 0"/>
      <!-- ${-PI_2} -->
      <geometry>
        <mesh filename="package://dobot_description/meshes/hand.dae" scale="1 1 1"/>
      </geometry>
    </visual>
    <collision name="hand_col">
      <origin rpy="0 0 0" xyz="0.05 0 0.005"/>
      <geometry>
        <box size="0.1 0.02 0.05"/>
      </geometry>
    </collision>
  </link>
  <joint name="Dobot_Rail_hand_joint" type="revolute">
    <parent link="Dobot_Rail_elbow_link"/>
    <child link="Dobot_Rail_hand_link"/>
    <origin rpy="0.0 0 0.0" xyz="0.147 0.0 0.0"/>
    <!-- 0 ${PI_2} 0 -->
    <axis xyz="0 1 0"/>
    <dynamics damping="1.0" friction="1.0"/>
    <limit effort="50.0" lower="-3.0" upper="3.0" velocity="3.1415"/>
  </joint>
  <gazebo reference="Dobot_Rail_hand_joint">
    <implicitSpringDamper>True</implicitSpringDamper>
  </gazebo>
  <!-- 
\t\t<transmission name="${name}_hand_transmission">
\t\t\t<type>transmission_interface/SimpleTransmission</type>
\t\t\t<joint name="${name}_hand_joint">
\t\t\t\t<hardwareInterface>hardware_interface/VelocityJointInterface</hardwareInterface>
\t\t\t</joint>
\t\t\t<actuator name="${name}_hand_motor">
\t\t\t\t<hardwareInterface>hardware_interface/VelocityJointInterface</hardwareInterface>
\t\t\t\t<mechanicalReduction>1</mechanicalReduction>
\t\t\t</actuator>
\t\t</transmission> -->
  <link name="Dobot_Rail_tool_link">
    <inertial>
      <origin rpy="0 0 0" xyz="0 0 0.0"/>
      <mass value="0.1"/>
      <inertia ixx="2.13020833333e-05" ixy="0" ixz="0" iyy="2.13020833333e-05" iyz="0" izz="9.375e-07"/>
    </inertial>
    <visual name="base_vis">
      <origin rpy="0 -0.0 0" xyz="0 0 0"/>
      <geometry>
        <mesh filename="package://dobot_description/meshes/suctionTool.dae" scale="1 1 1"/>
      </geometry>
    </visual>
    <collision name="tool_col">
      <origin rpy="0 0 0" xyz="0 0 -0.01"/>
      <geometry>
        <cylinder length="0.04" radius="0.0075"/>
      </geometry>
    </collision>
  </link>
  <joint name="Dobot_Rail_tool_joint" type="revolute">
    <parent link="Dobot_Rail_hand_link"/>
    <child link="Dobot_Rail_tool_link"/>
    <origin rpy="0 0 0" xyz="0.069 0.0 0.0"/>
    <axis xyz="0 0 1"/>
    <dynamics damping="1.0" friction="1.0"/>
    <limit effort="5.0" lower="-3.0" upper="3.0" velocity="3.1415"/>
  </joint>
  <gazebo reference="Dobot_Rail_tool_joint">
    <implicitSpringDamper>True</implicitSpringDamper>
  </gazebo>
  <transmission name="Dobot_Rail_tool_transmission">
    <type>transmission_interface/SimpleTransmission</type>
    <joint name="Dobot_Rail_tool_joint">
      <hardwareInterface>hardware_interface/EffortJointInterface</hardwareInterface>
    </joint>
    <actuator name="Dobot_Rail_tool_motor">
      <hardwareInterface>hardware_interface/EffortJointInterface</hardwareInterface>
      <mechanicalReduction>1</mechanicalReduction>
    </actuator>
  </transmission>
  <link name="Dobot_Rail_gripper_link">
    <inertial>
      <origin rpy="0 0 0" xyz="0 0 -0.035"/>
      <mass value="0.1"/>
      <inertia ixx="4.41666666667e-05" ixy="0" ixz="0" iyy="4.41666666667e-05" iyz="0" izz="6.66666666667e-06"/>
    </inertial>
    <visual name="base_vis">
      <origin rpy="0 -0.0 0" xyz="0 0 -0.00125"/>
      <geometry>
        <mesh filename="package://dobot_description/meshes/suction.dae" scale="1 1 1"/>
      </geometry>
    </visual>
    <collision name="tool_col">
      <origin rpy="0 0 0" xyz="0 0 -0.045"/>
      <geometry>
        <cylinder length="0.03" radius="0.01"/>
      </geometry>
    </collision>
    <collision name="suction_col">
      <origin rpy="0 0 0" xyz="0 0 -0.061"/>
      <geometry>
        <cylinder length="0.001" radius="0.0125"/>
      </geometry>
    </collision>
  </link>
  <joint name="Dobot_Rail_gripper_joint" type="prismatic">
    <parent link="Dobot_Rail_tool_link"/>
    <child link="Dobot_Rail_gripper_link"/>
    <origin rpy="0 0 0" xyz="0.0 0.0 0.0"/>
    <axis xyz="0 0 1"/>
    <dynamics damping="1.0" friction="1.0"/>
    <limit effort="10.0" lower="-0.001" upper="0.01" velocity="0.5"/>
  </joint>
  <gazebo reference="Dobot_Rail_gripper_joint">
    <implicitSpringDamper>True</implicitSpringDamper>
  </gazebo>
</robot>

